load the dataset
isic
get train set
Traceback (most recent call last):
  File "/home/primmere/.conda/envs/dfr2/lib/python3.10/site-packages/pandas/core/indexes/base.py", line 3805, in get_loc
    return self._engine.get_loc(casted_key)
  File "index.pyx", line 167, in pandas._libs.index.IndexEngine.get_loc
  File "index.pyx", line 196, in pandas._libs.index.IndexEngine.get_loc
  File "pandas/_libs/hashtable_class_helper.pxi", line 7081, in pandas._libs.hashtable.PyObjectHashTable.get_item
  File "pandas/_libs/hashtable_class_helper.pxi", line 7089, in pandas._libs.hashtable.PyObjectHashTable.get_item
KeyError: 'y'

The above exception was the direct cause of the following exception:

Traceback (most recent call last):
  File "/home/primmere/ide/external/pruning_by_explaining/my_experiments/my_global_pruning.py", line 329, in <module>
    start()
  File "/home/primmere/.conda/envs/dfr2/lib/python3.10/site-packages/click/core.py", line 1157, in __call__
    return self.main(*args, **kwargs)
  File "/home/primmere/.conda/envs/dfr2/lib/python3.10/site-packages/click/core.py", line 1078, in main
    rv = self.invoke(ctx)
  File "/home/primmere/.conda/envs/dfr2/lib/python3.10/site-packages/click/core.py", line 1434, in invoke
    return ctx.invoke(self.callback, **ctx.params)
  File "/home/primmere/.conda/envs/dfr2/lib/python3.10/site-packages/click/core.py", line 783, in invoke
    return __callback(*args, **kwargs)
  File "/home/primmere/ide/external/pruning_by_explaining/my_experiments/my_global_pruning.py", line 104, in start
    train_set = isic.get_train_set()
  File "/home/primmere/ide/external/pruning_by_explaining/my_datasets/isic_data.py", line 112, in get_train_set
    return ISICDataset(
  File "/home/primmere/ide/external/pruning_by_explaining/my_datasets/isic_data.py", line 50, in __init__
    self.y_array = self.metadata['y'].values
  File "/home/primmere/.conda/envs/dfr2/lib/python3.10/site-packages/pandas/core/frame.py", line 4102, in __getitem__
    indexer = self.columns.get_loc(key)
  File "/home/primmere/.conda/envs/dfr2/lib/python3.10/site-packages/pandas/core/indexes/base.py", line 3812, in get_loc
    raise KeyError(key) from err
KeyError: 'y'
Traceback (most recent call last):
  File "/home/primmere/.conda/envs/dfr2/lib/python3.10/site-packages/pandas/core/indexes/base.py", line 3805, in get_loc
    return self._engine.get_loc(casted_key)
  File "index.pyx", line 167, in pandas._libs.index.IndexEngine.get_loc
  File "index.pyx", line 196, in pandas._libs.index.IndexEngine.get_loc
  File "pandas/_libs/hashtable_class_helper.pxi", line 7081, in pandas._libs.hashtable.PyObjectHashTable.get_item
  File "pandas/_libs/hashtable_class_helper.pxi", line 7089, in pandas._libs.hashtable.PyObjectHashTable.get_item
KeyError: 'y'

The above exception was the direct cause of the following exception:

Traceback (most recent call last):
  File "/home/primmere/ide/external/pruning_by_explaining/my_experiments/my_global_pruning.py", line 329, in <module>
    start()
  File "/home/primmere/.conda/envs/dfr2/lib/python3.10/site-packages/click/core.py", line 1157, in __call__
    return self.main(*args, **kwargs)
  File "/home/primmere/.conda/envs/dfr2/lib/python3.10/site-packages/click/core.py", line 1078, in main
    rv = self.invoke(ctx)
  File "/home/primmere/.conda/envs/dfr2/lib/python3.10/site-packages/click/core.py", line 1434, in invoke
    return ctx.invoke(self.callback, **ctx.params)
  File "/home/primmere/.conda/envs/dfr2/lib/python3.10/site-packages/click/core.py", line 783, in invoke
    return __callback(*args, **kwargs)
  File "/home/primmere/ide/external/pruning_by_explaining/my_experiments/my_global_pruning.py", line 104, in start
    train_set = isic.get_train_set()
  File "/home/primmere/ide/external/pruning_by_explaining/my_datasets/isic_data.py", line 112, in get_train_set
    return ISICDataset(
  File "/home/primmere/ide/external/pruning_by_explaining/my_datasets/isic_data.py", line 50, in __init__
    self.y_array = self.metadata['y'].values
  File "/home/primmere/.conda/envs/dfr2/lib/python3.10/site-packages/pandas/core/frame.py", line 4102, in __getitem__
    indexer = self.columns.get_loc(key)
  File "/home/primmere/.conda/envs/dfr2/lib/python3.10/site-packages/pandas/core/indexes/base.py", line 3812, in get_loc
    raise KeyError(key) from err
KeyError: 'y'
